Workbook

Sheet Sheet1
A1: Countries | B1: Period1 | C1: Period1End | D1: Period2 | E1: Period2End | F1: Period3 | G1: Period3End
A2: United Kingdom | B2: 1927 | C2: 1936 | D2: 1941 | E2: 1967 | F2: 2004 | G2: 2014
A3: United States of America | B3: 1926 | C3: 1936 | D3: 1943 | E3: 1951 | F3: 2005 | G3: 2015
A4: Japan | B4: 1925 | C4: 1936 | D4: 1987 | E4: 2017
A5: France | B5: 1926 | C5: 1938
A6: Norway | B6: 1984 | C6: 1996
A7: Finland | B7: 1987 | C7: 2001
A8: Sweden | B8: 1987 | C8: 2000
A9: Austria | B9: 2005 | C9: 2017
A10: Germany | B10: 2006 | C10: 2017
A11: Greece | B11: 2005 | C11: 2018
A12: Hungary | B12: 2005 | C12: 2017
A13: Ireland | B13: 2005 | C13: 2017
A14: Italy | B14: 2005 | C14: 2017
A15: Netherlands | B15: 2006 | C15: 2017
A16: Portugal | B16: 2007 | C16: 2017
A17: Spain | B17: 2005 | C17: 2017
C18: {=C2:C17-B2:B17} -> 9 | E18: {=E2:E17-D2:D17} -> 26 | G18: {=G2:G17-F2:F17} -> 10
A19: =AVERAGE(C18:C38) -> 12.857143 | C19: 10 | E19: 8 | G19: 10
A20: =STDEV(C18:C38) -> 5.2657926 | C20: 11 | E20: 30 | G20: 0
C21: 12 | E21: 0 | G21: 0
C22: 12 | E22: 0 | G22: 0
C23: 14 | E23: 0 | G23: 0
C24: 13 | E24: 0 | G24: 0
C25: 12 | E25: 0 | G25: 0
C26: 11 | E26: 0 | G26: 0
C27: 13 | E27: 0 | G27: 0
C28: 12 | E28: 0 | G28: 0
C29: 12 | E29: 0 | G29: 0
C30: 12 | E30: 0 | G30: 0
C31: 11 | E31: 0 | G31: 0
C32: 10 | E32: 0 | G32: 0
C33: 12 | E33: 0 | G33: 0
C34: {=E18:E20} -> 26
C35: 8
C36: 30
C37: {=G18:G19} -> 10
C38: 10

Sheet Database
A1: Year | B1: Country | C1: BDG | D1: CoreInflation | E1: ChangeDebt/GDP | F1: SRi | G1: Money0/GDP | H1: R.GDPg | I1: Curve | J1: Equityg | K1: R.FXxTWI | L1: Gold Price
A2: =Sheet1!B2 -> 1927 | B2: United Kingdom | C2: 0.28199117 | D2: 0.37353792 | E2: -1.3506502 | F2: 4.0868556 | G2: 11.987469 | H2: 0.23064702 | I2: -0.072862342 | J2: 85.70611 | K2: 4.1054955 | L2: 107.07419
A3: =A2+1 -> 1928 | B3: United Kingdom | C3: 0.71689755 | D3: -2.5589234 | E3: -0.39971815 | F3: 4.0350264 | G3: 12.066902 | H3: 6.4975207 | I3: -0.24342476 | J3: 94.664198 | K3: 9.422167 | L3: 107.15496
A4: =A3+1 -> 1929 | B4: United Kingdom | C4: 0.738362 | D4: -0.45126399 | E4: -1.8073794 | F4: 5.4156717 | G4: 12.28637 | H4: 2.5388744 | I4: -0.038194575 | J4: 99.622959 | K4: 7.1643626 | L4: 105.82591
A5: =A4+1 -> 1930 | B5: United Kingdom | C5: 0.26495661 | D5: 0.23657402 | E5: -1.2875536 | F5: 2.1033852 | G5: 11.644058 | H5: 0.75568072 | I5: -2.2639103 | J5: 85.347024 | K5: 8.8740715 | L5: 105.82591
A6: =A5+1 -> 1931 | B6: United Kingdom | C6: -1.7358959 | D6: -3.4323984 | E6: 2.6683108 | F6: 4.5810497 | G6: 12.075461 | H6: -3.7844454 | I6: -2.1523281 | J6: 62.446277 | K6: 11.496788 | L6: 105.90179
A7: =A6+1 -> 1932 | B7: United Kingdom | C7: -2.8903638 | D7: -1.2077726 | E7: 4.1531612 | F7: 0.56457474 | G7: 11.524908 | H7: -5.3918977 | I7: 1.1567178 | J7: 40.645234 | K7: -10.374693 | L7: 128.4883
A8: =A7+1 -> 1933 | B8: United Kingdom | C8: -3.0129852 | D8: -3.2369513 | E8: 3.3931202 | F8: 0.091035764 | G8: 11.785805 | H8: 0.60201232 | I8: -2.5143886 | J8: 65.864333 | K8: -15.595411 | L8: 140.50849
A9: =A8+1 -> 1934 | B9: United Kingdom | C9: -1.0919622 | D9: -0.68029179 | E9: -0.16174492 | F9: 0.85183465 | G9: 13.475126 | H9: 7.2357019 | I9: -2.3576333 | J9: 85.308871 | K9: 3.444001 | L9: 153.24094
A10: =A9+1 -> 1935 | B10: United Kingdom | C10: -0.51255899 | D10: -0.33014715 | E10: -5.1159439 | F10: 0.208273 | G10: 12.787277 | H10: 4.8211535 | I10: -2.4581848 | J10: 86.692476 | K10: -0.075731543 | L10: 171.62001
A11: =A10+1 -> 1936 | B11: United Kingdom | C11: -0.015177348 | D11: 0.87385235 | E11: -6.416309 | F11: 0.49323789 | G11: 12.641079 | H11: 3.8526382 | I11: -2.4396503 | J11: 95.576502 | K11: 2.2722106 | L11: 178.69849
A12: 1926 | B12: United States | F12: 3.4284084 | G12: 6.8628771 | H12: 6.3893175 | I12: -0.18629352 | J12: 44.346243 | K12: 8.7125749 | L12: 0
A13: =A12+1 -> 1927 | B13: United States | C13: 0.8 | D13: 2.5 | E13: 0.7 | F13: 2.7180289 | G13: 6.6657914 | H13: 1.2234462 | I13: 0.17969313 | J13: 55.17704 | K13: 2.6497006 | L13: 0
A14: =A13+1 -> 1928 | B14: United States | C14: 1.05 | D14: 2 | E14: 2.2 | F14: 4.528083 | G14: 6.5768026 | H14: 1.0245622 | I14: 1.0362006 | J14: 73.222453 | K14: 3.4580838 | L14: 0
A15: =A14+1 -> 1929 | B15: United States | C15: 1.3 | D15: 3.8 | E15: 2.35 | F15: 3.1678007 | G15: 6.436677 | H15: 6.4649419 | I15: 2.1251434 | J15: 108.77593 | K15: 0.76347305 | L15: 0
A16: =A15+1 -> 1930 | B16: United States | C16: 0.1 | D16: 1.27 | E16: 4.65 | F16: 1.661398 | G16: 6.4688877 | H16: -6.1532941 | I16: 0.054610628 | J16: 76.377132 | K16: 3.997006 | L16: 0
A17: =A16+1 -> 1931 | B17: United States | C17: -2.48 | D17: -6.7 | E17: 13 | F17: 1.5402544 | G17: 7.4710585 | H17: -7.0196103 | I17: -1.6258695 | J17: 49.6503 | K17: 15.04491 | L17: 0
A18: =A17+1 -> 1932 | B18: United States | C18: -3.4 | D18: -8.9 | E18: 27.8 | F18: 0.03442228 | G18: 9.1642121 | H18: -11.898055 | I18: -2.1910864 | J18: 28.072614 | K18: 23.802395 | L18: 0
A19: =A18+1 -> 1933 | B19: United States | C19: -3 | D19: -6.2 | E19: 30 | F19: 0.12196771 | G19: 9.7398188 | H19: -2.828513 | I19: -3.3231044 | J19: 38.395113 | K19: -3.4131737 | L19: 0
A20: =A19+1 -> 1934 | B20: United States | C20: -2.1 | D20: 6.2 | E20: 13.1 | F20: 0.14675429 | G20: 11.168554 | H20: 9.2035668 | I20: -3.1030372 | J20: 34.3142 | K20: -9.4760479 | L20: 0
A21: =A20+1 -> 1935 | B21: United States | C21: -1.4 | D21: 5.9 | E21: -8.2 | F21: 0.024469614 | G21: 11.74416 | H21: 9.5792665 | I21: -3.0288894 | J21: 43.618488 | K21: -2.4700599 | L21: 0
A22: =A21+1 -> 1936 | B22: United States | C22: -0.18 | D22: 5.8 | E22: -19.4 | F22: 0.13337841 | G22: 12.685003 | H22: 12.343458 | I22: -2.7934077 | J22: 53.416551 | K22: -6.6467066 | L22: 0
A23: 1925 | B23: Japan | C23: -0.6371064 | D23: -1.3471614 | E23: 4.5235066 | F23: 5.8362351 | G23: 0 | H23: 3.0641391 | I23: 1.1144459 | J23: 68.199149 | K23: 5.603979 | L23: 125.48284
A24: =A23+1 -> 1926 | B24: Japan | C24: 0.27741439 | D24: -9.0513301 | E24: 3.95437 | F24: 6.5147388 | G24: 0 | H24: 2.6749427 | I24: 1.0099583 | J24: 92.733652 | K24: 11.061628 | L24: 112.48903
A25: =A24+1 -> 1927 | B25: Japan | C25: 0.98421004 | D25: -5.5497607 | E25: 3.4443335 | F25: 5.3245992 | G25: 0 | H25: 1.5867584 | I25: 0.36906526 | J25: 95.986399 | K25: 13.297428 | L25: 102.24437
A26: =A25+1 -> 1928 | B26: Japan | C26: 0.48955751 | D26: -4.7742598 | E26: 4.0489735 | F26: 2.2768488 | G26: 0 | H26: 5.0481463 | I26: -2.9860541 | J26: 86.592792 | K26: 8.7514274 | L26: 106.32768
A27: =A26+1 -> 1929 | B27: Japan | C27: 0.50747039 | D27: 1.9012782 | E27: 4.463324 | F27: 2.5512843 | G27: 0 | H27: 5.3165576 | I27: -2.7331514 | J27: 82.581843 | K27: 6.914945 | L27: 105.30888
A28: =A27+1 -> 1930 | B28: Japan | C28: -0.19105159 | D28: -2.1122794 | E28: 5.7992471 | F28: 2.8829512 | G28: 0 | H28: 0.47508807 | I28: -2.4454905 | J28: 68.202043 | K28: 10.339278 | L28: 109.39218
A29: =A28+1 -> 1931 | B29: Japan | C29: -1.8885982 | D29: -15.966393 | E29: 10.071776 | F29: 2.0355111 | G29: 0 | H29: -3.9872505 | I29: -2.5141538 | J29: 60.593973 | K29: 3.1798222 | L29: 99.107102
A30: =A29+1 -> 1932 | B30: Japan | C30: -1.3518544 | D30: -2.5465742 | E30: 11.003307 | F30: 6.0410274 | G30: 0 | H30: 4.2160711 | I30: 0.059760531 | J30: 50.69104 | K30: 13.903938 | L30: 143.06935
A31: =A30+1 -> 1933 | B31: Japan | C31: 1.2409345 | D31: 5.7999069 | E31: 8.55011 | F31: 3.1415273 | G31: 0 | H31: 9.2398367 | I31: -2.1166743 | J31: 44.014807 | K31: -43.374536 | L31: 237.22797
A32: =A31+1 -> 1934 | B32: Japan | C32: 2.9095635 | D32: 2.7899178 | E32: 1.7258831 | F32: 2.3988967 | G32: 0 | H32: 5.5301683 | I32: -2.2563466 | J32: 76.248538 | K32: -25.643534 | L32: 275.69191
A33: =A32+1 -> 1935 | B33: Japan | C33: 1.5912398 | D33: 1.5024287 | E33: -2.3801701 | F33: 2.2802965 | G33: 0 | H33: 2.437846 | I33: -2.2188163 | J33: 64.599134 | K33: -27.480016 | L33: 285.21693
A34: =A33+1 -> 1936 | B34: Japan | C34: 0.72266593 | D34: 2.4458474 | E34: -2.5195858 | F34: 2.2685744 | G34: 0 | H34: 4.6220433 | I34: -2.1458882 | J34: 70.081632 | K34: -23.464242 | L34: 292.21919
A35: 1926 | B35: France | C35: 1.3571352 | D35: 23.576193 | E35: -36.297961 | F35: 4.3754941 | G35: 0 | H35: 3.17246 | I35: -0.73362861 | J35: 33.10996 | K35: -34.531227 | L35: 112.2688
A36: =A35+1 -> 1927 | B36: France | C36: 0.65794671 | D36: 35.24085 | E36: -29.869845 | F36: 1.9565217 | G36: 0 | H36: 1.6317947 | I36: 1.915407 | J36: 46.083724 | K36: -13.427947 | L36: 165.0811
A37: =A36+1 -> 1928 | B37: France | C37: 0.79132227 | D37: -16.011273 | E37: -10.457392 | F37: 2.7747036 | G37: 0 | H37: 3.6556895 | I37: -1.4591971 | J37: 68.664912 | K37: -17.681652 | L37: 107.01888
A38: =A37+1 -> 1929 | B38: France | C38: 2.0848773 | D38: 13.770645 | E38: -10.841699 | F38: 3.3794466 | G38: 0 | H38: 8.0088691 | I38: -0.91007648 | J38: 99.922407 | K38: -8.4782503 | L38: 109.45177
A39: =A38+1 -> 1930 | B39: France | C39: 2.3456923 | D39: 2.5798115 | E39: -5.1082918 | F39: 1.8498024 | G39: 0 | H39: 5.6142089 | I39: -0.31313574 | J39: 86.359369 | K39: -8.6260024 | L39: 109.45177
A40: =A39+1 -> 1931 | B40: France | C40: 0.49759548 | D40: 6.0499175 | E40: -0.8825522 | F40: 1.0671937 | G40: 0 | H40: -2.7716737 | I40: -1.1047563 | J40: 70.885265 | K40: 2.6925881 | L40: 106.70587
...

Sheet Forecast
A1: Year | B1: Country | C1: ChangeDebt/GDP | D1: SRi | E1: Curve | F1: R.GDPg | G1: CoreInflation | H1: Money0/GDP | I1: Equityg | J1: R.FXxTWI | K1: Gold_Price | L1: BDG | N1: 18.8 | O1: 104.6 | Q1: 3.35 | R1: {=Q1:Q10/N1:N10} -> 0.17819149 | U1: M0 Supply | V1: GDP | Y1: M1 Supply
A2: 2017 | B2: United States | C2: 0.013 | D2: 0.01 | E2: 0.014 | F2: 0.025 | G2: 0.018 | H2: {=_xlfn.ANCHORARRAY(W2)} -> 0.18333068 | I2: 953 | J2: 94.4 | K2: 1302.8 | M2: 20.5 | N2: 19.6 | O2: {=M2:M9/N2:N9*100} -> 104.59184 | P2: =(O2-O1)/O1 -> -7.8042689e-05 | Q2: 3.6 | R2: 0.18367347 | S2: =(R2-R1)/R1 -> 0.030764545 | U2: 3595500 | V2: 19612102 | W2: {=U2:U10/V2:V10} -> 0.18333068 | X2: 3524533 | Y2: {=X2:X10/V2:V10} -> 0.17971215
A3: 2018 | B3: United States | C3: 0.02 | D3: 0.0183 | E3: 0.0085 | F3: 0.03 | G3: 0.022 | H3: 0.18516191 | I3: 894 | J3: 98.6 | K3: 1282.5 | M3: 22 | N3: 20.6 | O3: 106.79612 | P3: =(O3-O2)/O2 -> 0.021075065 | Q3: 3.7 | R3: 0.17961165 | S3: =(R3-R2)/R2 -> -0.022114347 | U3: 3824800 | V3: 20656516 | W3: 0.18516191 | X3: 3680583 | Y3: 0.17818024
A4: 2019 | B4: United States | C4: 0.01 | D4: 0.0216 | E4: -0.0025 | F4: 0.026 | G4: 0.023 | H4: 0.15538082 | I4: 1155 | J4: 98.1 | K4: 1517.3 | M4: 23.2 | N4: 21.5 | O4: 107.90698 | P4: =(O4-O3)/O3 -> 0.010401691 | Q4: 4 | R4: 0.18604651 | S4: =(R4-R3)/R3 -> 0.035826524 | U4: 3346900 | V4: 21539982 | W4: 0.15538082 | X4: 3845317 | Y4: 0.17851997
A5: 2020 | B5: United States | C5: 0.209 | D5: 0.0036 | E5: 0.0055 | F5: -0.021 | G5: 0.016 | H5: 0.16121491 | I5: 1380 | J5: 95 | K5: 1898.4 | M5: 27.8 | N5: 21.3 | O5: 130.51643 | P5: =(O5-O4)/O4 -> 0.20952728 | Q5: 17.8 | R5: 0.83568075 | S5: =(R5-R4)/R4 -> 3.491784 | U5: 3442600 | V5: 21354104 | W5: 0.16121491 | X5: 12781800 | Y5: 0.5985641
A6: 2021 | B6: United States | C6: -0.04 | D6: 0.0008 | E6: 0.0143 | F6: 0.062 | G6: 0.055 | H6: 0.22161067 | I6: 1733 | J6: 101 | K6: 1829.2 | M6: 29.6 | N6: 23.7 | O6: 124.89451 | P6: =(O6-O5)/O5 -> -0.043074401 | Q6: 20.4 | R6: 0.86075949 | S6: =(R6-R5)/R5 -> 0.030009956 | U6: 5248000 | V6: 23681170 | W6: 0.22161067 | X6: 19355340 | Y6: 0.81733039
A7: 2022 | B7: United States | C7: -0.03 | D7: 0.0168 | E7: 0.0219 | F7: 0.025 | G7: 0.057 | H7: 0.23470317 | I7: 1369 | J7: 107.5 | K7: 1824 | M7: 31.4 | N7: 26 | O7: 120.76923 | P7: =(O7-O6)/O6 -> -0.033030146 | Q7: 19.6 | R7: 0.75384615 | S7: =(R7-R6)/R6 -> -0.12420814 | U7: 6103900 | V7: 26006892 | W7: 0.23470317 | X7: 20395950 | Y7: 0.78425173
A8: 2023 | B8: United States | C8: 0.012 | D8: 0.0503 | E8: -0.0115 | F8: 0.029 | G8: 0.039 | H8: 0.19223894 | I8: 1719 | J8: 108.4 | K8: 2063 | M8: 34 | N8: 27.8 | O8: 122.30216 | P8: =(O8-O7)/O7 -> 0.01269303 | Q8: 17.9 | R8: 0.64388489 | S8: =(R8-R7)/R7 -> -0.14586698 | U8: 5329000 | V8: 27720710 | W8: 0.19223894 | X8: 18500880 | Y8: 0.66740282
A9: 2024 | B9: United States | C9: 0.01 | D9: 0.0515 | E9: -0.0059 | F9: 0.028 | G9: 0.032 | H9: 0.20032105 | I9: 2124 | J9: 113.4 | K9: 2624 | M9: 36.2 | N9: 29.3 | O9: 123.54949 | P9: =(O9-O8)/O8 -> 0.010198755 | Q9: 18.3 | R9: 0.62457338 | S9: =(R9-R8)/R8 -> -0.029992183 | U9: 5843300 | V9: 29169676 | W9: 0.20032105 | X9: 18092220 | Y9: 0.62024069
A10: 2025 | B10: United States | C10: -0.03 | D10: 0.037 | E10: 0.003 | F10: 0.018 | G10: 0.03 | H10: 0.18426116 | I10: 2480 | J10: 108.7 | K10: 4002 | N10: =N9*(1+0.03) -> 30.179 | O10: 120 | P10: =(O10-O9)/O9 -> -0.028729282 | Q10: 19 | R10: 0.62957686 | S10: =(R10-R9)/R9 -> 0.0080110351 | U10: 5613900 | V10: 30467082 | W10: 0.18426116 | X10: 18594152 | Y10: 0.61030301
A11: {=A1:K1} -> Year | B11: Country | C11: ChangeDebt/GDP | D11: SRi | E11: Curve | F11: R.GDPg | G11: CoreInflation | H11: Money0/GDP | I11: Equityg | J11: R.FXxTWI | K11: Gold_Price | L11: =L1 -> BDG | N11: W/OG_All | O11: WG_All | P11: UK30s | Q11: US30s | R11: JPY30s | S11: Fr30s | T11: =I23 -> UK40s | U11: 30s50s | V11: JPY | W11: SKY80s | X11: 08s | Y11: GFI | AB11: BDG_pred_splines_ridge
A12: {=A2:B10} -> 2017 | B12: United States | C12: {=C2:H10*100} -> 1.3 | D12: 1 | E12: 1.4 | F12: 2.5 | G12: 1.8 | H12: 18.333068 | I12: 0.1 | J12: 1 | K12: {=K2:K10} -> 1302.8 | L12: =$B$24+C12*$B$26+D12*$B$27+E12*$B$30+F12*$B$29+$B$25*G12+H12*$B$28+I12*$B$31+J12*$B$32+K12*$B$33 -> -0.52670068 | M12: 0.13 | N12: =$D$24+C12*$D$26+D12*$D$27+E12*$D$30+F12*$D$29+G12*$D$25+H12*$D$28+I12*$D$31+J12*$D$32 -> -0.027225041 | O12: =$C$24+C12*$C$26+D12*$C$27+E12*$C$30+F12*$C$29+G12*$C$25+H12*$C$28+I12*$C$31+J12*$C$32+M12*$C$33 -> -0.10798799 | P12: =E$24+$C12*E$26+$D12*E$27+$E12*E$30+$F12*E$29+$G12*E$25+$H12*E$28+$I12*E$31+$J12*E$32 -> -5.4706486 | Q12: =F$24+$C12*F$26+$D12*F$27+$E12*F$30+$F12*F$29+$G12*F$25+$H12*F$28+$I12*F$31+$J12*F$32 -> -1.3959337 | R12: =G$24+$C12*G$26+$D12*G$27+$E12*G$30+$F12*G$29+$G12*G$25+$H12*G$28+$I12*G$31+$J12*G$32 -> -5.9098945 | S12: =H$24+$C12*H$26+$D12*H$27+$E12*H$30+$F12*H$29+$G12*H$25+$H12*H$28+$I12*H$31+$J12*H$32 -> 1.4077193 | T12: =I$24+$C12*I$26+$D12*I$27+$E12*I$30+$F12*I$29+$G12*I$25+$H12*I$28+$I12*I$31+$J12*I$32 -> -1.5681875 | U12: =J$24+$C12*J$26+$D12*J$27+$E12*J$30+$F12*J$29+$G12*J$25+$H12*J$28+$I12*J$31+$J12*J$32 -> 0.38695544 | V12: =K$24+$C12*K$26+$D12*K$27+$E12*K$30+$F12*K$29+$G12*K$25+$H12*K$28+$I12*K$31+$J12*K$32+$M12*K$33 -> -0.18522322 | W12: =L$24+$C12*L$26+$D12*L$27+$E12*L$30+$F12*L$29+$G12*L$25+$H12*L$28+$I12*L$31+$J12*L$32+$M12*L$33 -> -1.2163457 | X12: =M$24+$C12*M$26+$D12*M$27+$E12*M$30+$F12*M$29+$G12*M$25+$H12*M$28+$I12*M$31+$J12*M$32+$M12*M$33 -> -0.12785071 | Y12: =N$24+$C12*N$26+$D12*N$27+$E12*N$30+$F12*N$29+$G12*N$25+$H12*N$28+$I12*N$31+$J12*N$32+N$33*M12 -> 1.8924663 | Z12: =O$24+$C12*O$26+$D12*O$27+$E12*O$30+$F12*O$29+$G12*O$25+$H12*O$28+$I12*O$31+$J12*O$32 -> -0.041233076 | AA12: -0.28 | AB12: -0.038597023
A13: 2018 | B13: United States | C13: 2 | D13: 1.83 | E13: 0.85 | F13: 3 | G13: 2.2 | H13: 18.516191 | I13: =I3/I2-1 -> -0.061909759 | J13: =(J3/J2-1)*100 -> 4.4491525 | K13: 1282.5 | L13: =$B$24+C13*$B$26+D13*$B$27+E13*$B$30+F13*$B$29+$B$25*G13+H13*$B$28+I13*$B$31+J13*$B$32+K13*$B$33 -> -0.47764719 | M13: =K13/K12-1 -> -0.015581824 | N13: =$D$24+C13*$D$26+D13*$D$27+E13*$D$30+F13*$D$29+G13*$D$25+H13*$D$28+I13*$D$31+J13*$D$32 -> 0.045555169 | O13: =$C$24+C13*$C$26+D13*$C$27+E13*$C$30+F13*$C$29+G13*$C$25+H13*$C$28+I13*$C$31+J13*$C$32+M13*$C$33 -> 0.11062813 | P13: =E$24+$C13*E$26+$D13*E$27+$E13*E$30+$F13*E$29+$G13*E$25+$H13*E$28+$I13*E$31+$J13*E$32 -> -5.0873085 | Q13: =F$24+$C13*F$26+$D13*F$27+$E13*F$30+$F13*F$29+$G13*F$25+$H13*F$28+$I13*F$31+$J13*F$32 -> -1.6054336 | R13: =G$24+$C13*G$26+$D13*G$27+$E13*G$30+$F13*G$29+$G13*G$25+$H13*G$28+$I13*G$31+$J13*G$32 -> -4.4134057 | S13: =H$24+$C13*H$26+$D13*H$27+$E13*H$30+$F13*H$29+$G13*H$25+$H13*H$28+$I13*H$31+$J13*H$32 -> 1.4537362 | T13: =I$24+$C13*I$26+$D13*I$27+$E13*I$30+$F13*I$29+$G13*I$25+$H13*I$28+$I13*I$31+$J13*I$32 -> -3.1568253 | U13: =J$24+$C13*J$26+$D13*J$27+$E13*J$30+$F13*J$29+$G13*J$25+$H13*J$28+$I13*J$31+$J13*J$32 -> 0.27725575 | V13: =K$24+$C13*K$26+$D13*K$27+$E13*K$30+$F13*K$29+$G13*K$25+$H13*K$28+$I13*K$31+$J13*K$32+$M13*K$33 -> -0.10295683 | W13: =L$24+$C13*L$26+$D13*L$27+$E13*L$30+$F13*L$29+$G13*L$25+$H13*L$28+$I13*L$31+$J13*L$32+$M13*L$33 -> -0.86606297 | X13: =M$24+$C13*M$26+$D13*M$27+$E13*M$30+$F13*M$29+$G13*M$25+$H13*M$28+$I13*M$31+$J13*M$32+$M13*M$33 -> 0.53330872 | Y13: =N$24+$C13*N$26+$D13*N$27+$E13*N$30+$F13*N$29+$G13*N$25+$H13*N$28+$I13*N$31+$J13*N$32+N$33*M13 -> 2.4482803 | Z13: =O$24+$C13*O$26+$D13*O$27+$E13*O$30+$F13*O$29+$G13*O$25+$H13*O$28+$I13*O$31+$J13*O$32 -> 0.073655987 | AA13: -0.2 | AB13: -0.062336156
A14: 2019 | B14: United States | C14: 1 | D14: 2.16 | E14: -0.25 | F14: 2.6 | G14: 2.3 | H14: 15.538082 | I14: =I4/I3-1 -> 0.29194631 | J14: =(J4/J3-1)*100 -> -0.50709939 | K14: 1517.3 | L14: =$B$24+C14*$B$26+D14*$B$27+E14*$B$30+F14*$B$29+$B$25*G14+H14*$B$28+I14*$B$31+J14*$B$32+K14*$B$33 -> -0.61898129 | M14: =K14/K13-1 -> 0.18307992 | N14: =$D$24+C14*$D$26+D14*$D$27+E14*$D$30+F14*$D$29+G14*$D$25+H14*$D$28+I14*$D$31+J14*$D$32 -> -0.0087385487 | O14: =$C$24+C14*$C$26+D14*$C$27+E14*$C$30+F14*$C$29+G14*$C$25+H14*$C$28+I14*$C$31+J14*$C$32+M14*$C$33 -> -0.14548062 | P14: =E$24+$C14*E$26+$D14*E$27+$E14*E$30+$F14*E$29+$G14*E$25+$H14*E$28+$I14*E$31+$J14*E$32 -> -2.6958995 | Q14: =F$24+$C14*F$26+$D14*F$27+$E14*F$30+$F14*F$29+$G14*F$25+$H14*F$28+$I14*F$31+$J14*F$32 -> -1.0290715 | R14: =G$24+$C14*G$26+$D14*G$27+$E14*G$30+$F14*G$29+$G14*G$25+$H14*G$28+$I14*G$31+$J14*G$32 -> -3.2830159 | S14: =H$24+$C14*H$26+$D14*H$27+$E14*H$30+$F14*H$29+$G14*H$25+$H14*H$28+$I14*H$31+$J14*H$32 -> 0.91975906 | T14: =I$24+$C14*I$26+$D14*I$27+$E14*I$30+$F14*I$29+$G14*I$25+$H14*I$28+$I14*I$31+$J14*I$32 -> -2.1796523 | U14: =J$24+$C14*J$26+$D14*J$27+$E14*J$30+$F14*J$29+$G14*J$25+$H14*J$28+$I14*J$31+$J14*J$32 -> 0.32840691 | V14: =K$24+$C14*K$26+$D14*K$27+$E14*K$30+$F14*K$29+$G14*K$25+$H14*K$28+$I14*K$31+$J14*K$32+$M14*K$33 -> 0.38037311 | W14: =L$24+$C14*L$26+$D14*L$27+$E14*L$30+$F14*L$29+$G14*L$25+$H14*L$28+$I14*L$31+$J14*L$32+$M14*L$33 -> -0.96743644 | X14: =M$24+$C14*M$26+$D14*M$27+$E14*M$30+$F14*M$29+$G14*M$25+$H14*M$28+$I14*M$31+$J14*M$32+$M14*M$33 -> -0.0047301289 | Y14: =N$24+$C14*N$26+$D14*N$27+$E14*N$30+$F14*N$29+$G14*N$25+$H14*N$28+$I14*N$31+$J14*N$32+N$33*M14 -> 0.71347526 | Z14: =O$24+$C14*O$26+$D14*O$27+$E14*O$30+$F14*O$29+$G14*O$25+$H14*O$28+$I14*O$31+$J14*O$32 -> -0.060893952 | AA14: -0.516 | AB14: -0.15392096
A15: 2020 | B15: United States | C15: 20.9 | D15: 0.36 | E15: 0.55 | F15: -2.1 | G15: 1.6 | H15: 16.121491 | I15: =I5/I4-1 -> 0.19480519 | J15: =(J5/J4-1)*100 -> -3.1600408 | K15: 1898.4 | L15: =$B$24+C15*$B$26+D15*$B$27+E15*$B$30+F15*$B$29+$B$25*G15+H15*$B$28+I15*$B$31+J15*$B$32+K15*$B$33 -> -1.1378481 | M15: =K15/K14-1 -> 0.25116984 | N15: =$D$24+C15*$D$26+D15*$D$27+E15*$D$30+F15*$D$29+G15*$D$25+H15*$D$28+I15*$D$31+J15*$D$32 -> -0.38189455 | O15: =$C$24+C15*$C$26+D15*$C$27+E15*$C$30+F15*$C$29+G15*$C$25+H15*$C$28+I15*$C$31+J15*$C$32+M15*$C$33 -> -0.50607885 | P15: =E$24+$C15*E$26+$D15*E$27+$E15*E$30+$F15*E$29+$G15*E$25+$H15*E$28+$I15*E$31+$J15*E$32 -> -6.85537 | Q15: =F$24+$C15*F$26+$D15*F$27+$E15*F$30+$F15*F$29+$G15*F$25+$H15*F$28+$I15*F$31+$J15*F$32 -> -2.1658063 | R15: =G$24+$C15*G$26+$D15*G$27+$E15*G$30+$F15*G$29+$G15*G$25+$H15*G$28+$I15*G$31+$J15*G$32 -> -10.187491 | S15: =H$24+$C15*H$26+$D15*H$27+$E15*H$30+$F15*H$29+$G15*H$25+$H15*H$28+$I15*H$31+$J15*H$32 -> 0.98211193 | T15: =I$24+$C15*I$26+$D15*I$27+$E15*I$30+$F15*I$29+$G15*I$25+$H15*I$28+$I15*I$31+$J15*I$32 -> 2.5593366 | U15: =J$24+$C15*J$26+$D15*J$27+$E15*J$30+$F15*J$29+$G15*J$25+$H15*J$28+$I15*J$31+$J15*J$32 -> 0.085440063 | V15: =K$24+$C15*K$26+$D15*K$27+$E15*K$30+$F15*K$29+$G15*K$25+$H15*K$28+$I15*K$31+$J15*K$32+$M15*K$33 -> -0.90612777 | W15: =L$24+$C15*L$26+$D15*L$27+$E15*L$30+$F15*L$29+$G15*L$25+$H15*L$28+$I15*L$31+$J15*L$32+$M15*L$33 -> -1.8391517 | X15: =M$24+$C15*M$26+$D15*M$27+$E15*M$30+$F15*M$29+$G15*M$25+$H15*M$28+$I15*M$31+$J15*M$32+$M15*M$33 -> -1.215805 | Y15: =N$24+$C15*N$26+$D15*N$27+$E15*N$30+$F15*N$29+$G15*N$25+$H15*N$28+$I15*N$31+$J15*N$32+N$33*M15 -> 0.81088067 | Z15: =O$24+$C15*O$26+$D15*O$27+$E15*O$30+$F15*O$29+$G15*O$25+$H15*O$28+$I15*O$31+$J15*O$32 -> -0.43952344 | AA15: -1.13 | AB15: -0.8740275
A16: 2021 | B16: United States | C16: -4 | D16: 0.08 | E16: 1.43 | F16: 6.2 | G16: 5.5 | H16: 22.161067 | I16: =I6/I5-1 -> 0.2557971 | J16: =(J6/J5-1)*100 -> 6.3157895 | K16: 1829.2 | L16: =$B$24+C16*$B$26+D16*$B$27+E16*$B$30+F16*$B$29+$B$25*G16+H16*$B$28+I16*$B$31+J16*$B$32+K16*$B$33 -> -0.069258937 | M16: =K16/K15-1 -> -0.036451749 | N16: =$D$24+C16*$D$26+D16*$D$27+E16*$D$30+F16*$D$29+G16*$D$25+H16*$D$28+I16*$D$31+J16*$D$32 -> 0.71845609 | O16: =$C$24+C16*$C$26+D16*$C$27+E16*$C$30+F16*$C$29+G16*$C$25+H16*$C$28+I16*$C$31+J16*$C$32+M16*$C$33 -> 0.79199265 | P16: =E$24+$C16*E$26+$D16*E$27+$E16*E$30+$F16*E$29+$G16*E$25+$H16*E$28+$I16*E$31+$J16*E$32 -> -6.4580538 | Q16: =F$24+$C16*F$26+$D16*F$27+$E16*F$30+$F16*F$29+$G16*F$25+$H16*F$28+$I16*F$31+$J16*F$32 -> -1.6863054 | R16: =G$24+$C16*G$26+$D16*G$27+$E16*G$30+$F16*G$29+$G16*G$25+$H16*G$28+$I16*G$31+$J16*G$32 -> -2.9828684 | S16: =H$24+$C16*H$26+$D16*H$27+$E16*H$30+$F16*H$29+$G16*H$25+$H16*H$28+$I16*H$31+$J16*H$32 -> 1.9087863 | T16: =I$24+$C16*I$26+$D16*I$27+$E16*I$30+$F16*I$29+$G16*I$25+$H16*I$28+$I16*I$31+$J16*I$32 -> -5.3930992 | U16: =J$24+$C16*J$26+$D16*J$27+$E16*J$30+$F16*J$29+$G16*J$25+$H16*J$28+$I16*J$31+$J16*J$32 -> 0.66227522 | V16: =K$24+$C16*K$26+$D16*K$27+$E16*K$30+$F16*K$29+$G16*K$25+$H16*K$28+$I16*K$31+$J16*K$32+$M16*K$33 -> 0.42561817 | W16: =L$24+$C16*L$26+$D16*L$27+$E16*L$30+$F16*L$29+$G16*L$25+$H16*L$28+$I16*L$31+$J16*L$32+$M16*L$33 -> 1.2005748 | X16: =M$24+$C16*M$26+$D16*M$27+$E16*M$30+$F16*M$29+$G16*M$25+$H16*M$28+$I16*M$31+$J16*M$32+$M16*M$33 -> 2.4472314 | Y16: =N$24+$C16*N$26+$D16*N$27+$E16*N$30+$F16*N$29+$G16*N$25+$H16*N$28+$I16*N$31+$J16*N$32+N$33*M16 -> 5.410104 | Z16: =O$24+$C16*O$26+$D16*O$27+$E16*O$30+$F16*O$29+$G16*O$25+$H16*O$28+$I16*O$31+$J16*O$32 -> 0.68171844 | AA16: 0.1 | AB16: 0.96547824
A17: 2022 | B17: United States | C17: -3 | D17: 1.68 | E17: 2.19 | F17: 2.5 | G17: 5.7 | H17: 23.470317 | I17: =I7/I6-1 -> -0.21004039 | J17: =(J7/J6-1)*100 -> 6.4356436 | K17: 1824 | L17: =$B$24+C17*$B$26+D17*$B$27+E17*$B$30+F17*$B$29+$B$25*G17+H17*$B$28+I17*$B$31+J17*$B$32+K17*$B$33 -> -0.54936288 | M17: =K17/K16-1 -> -0.0028427728 | N17: =$D$24+C17*$D$26+D17*$D$27+E17*$D$30+F17*$D$29+G17*$D$25+H17*$D$28+I17*$D$31+J17*$D$32 -> 0.24867504 | O17: =$C$24+C17*$C$26+D17*$C$27+E17*$C$30+F17*$C$29+G17*$C$25+H17*$C$28+I17*$C$31+J17*$C$32+M17*$C$33 -> 0.3015298 | P17: =E$24+$C17*E$26+$D17*E$27+$E17*E$30+$F17*E$29+$G17*E$25+$H17*E$28+$I17*E$31+$J17*E$32 -> -7.8282702 | Q17: =F$24+$C17*F$26+$D17*F$27+$E17*F$30+$F17*F$29+$G17*F$25+$H17*F$28+$I17*F$31+$J17*F$32 -> -1.6876394 | R17: =G$24+$C17*G$26+$D17*G$27+$E17*G$30+$F17*G$29+$G17*G$25+$H17*G$28+$I17*G$31+$J17*G$32 -> -2.7953217 | S17: =H$24+$C17*H$26+$D17*H$27+$E17*H$30+$F17*H$29+$G17*H$25+$H17*H$28+$I17*H$31+$J17*H$32 -> 1.3912816 | T17: =I$24+$C17*I$26+$D17*I$27+$E17*I$30+$F17*I$29+$G17*I$25+$H17*I$28+$I17*I$31+$J17*I$32 -> -6.9069926 | U17: =J$24+$C17*J$26+$D17*J$27+$E17*J$30+$F17*J$29+$G17*J$25+$H17*J$28+$I17*J$31+$J17*J$32 -> 0.49225323 | V17: =K$24+$C17*K$26+$D17*K$27+$E17*K$30+$F17*K$29+$G17*K$25+$H17*K$28+$I17*K$31+$J17*K$32+$M17*K$33 -> 0.79044557 | W17: =L$24+$C17*L$26+$D17*L$27+$E17*L$30+$F17*L$29+$G17*L$25+$H17*L$28+$I17*L$31+$J17*L$32+$M17*L$33 -> -0.15071566 | X17: =M$24+$C17*M$26+$D17*M$27+$E17*M$30+$F17*M$29+$G17*M$25+$H17*M$28+$I17*M$31+$J17*M$32+$M17*M$33 -> 1.5534734 | Y17: =N$24+$C17*N$26+$D17*N$27+$E17*N$30+$F17*N$29+$G17*N$25+$H17*N$28+$I17*N$31+$J17*N$32+N$33*M17 -> 4.5948693 | Z17: =O$24+$C17*O$26+$D17*O$27+$E17*O$30+$F17*O$29+$G17*O$25+$H17*O$28+$I17*O$31+$J17*O$32 -> 0.30363102 | AA17: 0.2 | AB17: 0.36701285
A18: 2023 | B18: United States | C18: 1.2 | D18: 5.03 | E18: -1.15 | F18: 2.9 | G18: 3.9 | H18: 19.223894 | I18: =I8/I7-1 -> 0.25566107 | J18: =(J8/J7-1)*100 -> 0.8372093 | K18: 2063 | L18: =$B$24+C18*$B$26+D18*$B$27+E18*$B$30+F18*$B$29+$B$25*G18+H18*$B$28+I18*$B$31+J18*$B$32+K18*$B$33 -> -0.74073109 | M18: =K18/K17-1 -> 0.1310307 | N18: =$D$24+C18*$D$26+D18*$D$27+E18*$D$30+F18*$D$29+G18*$D$25+H18*$D$28+I18*$D$31+J18*$D$32 -> 0.21924593 | O18: =$C$24+C18*$C$26+D18*$C$27+E18*$C$30+F18*$C$29+G18*$C$25+H18*$C$28+I18*$C$31+J18*$C$32+M18*$C$33 -> 0.13581245 | P18: =E$24+$C18*E$26+$D18*E$27+$E18*E$30+$F18*E$29+$G18*E$25+$H18*E$28+$I18*E$31+$J18*E$32 -> -4.5222608 | Q18: =F$24+$C18*F$26+$D18*F$27+$E18*F$30+$F18*F$29+$G18*F$25+$H18*F$28+$I18*F$31+$J18*F$32 -> -1.3588294 | R18: =G$24+$C18*G$26+$D18*G$27+$E18*G$30+$F18*G$29+$G18*G$25+$H18*G$28+$I18*G$31+$J18*G$32 -> 3.6770522 | S18: =H$24+$C18*H$26+$D18*H$27+$E18*H$30+$F18*H$29+$G18*H$25+$H18*H$28+$I18*H$31+$J18*H$32 -> 0.42343518 | T18: =I$24+$C18*I$26+$D18*I$27+$E18*I$30+$F18*I$29+$G18*I$25+$H18*I$28+$I18*I$31+$J18*I$32 -> -10.787876 | U18: =J$24+$C18*J$26+$D18*J$27+$E18*J$30+$F18*J$29+$G18*J$25+$H18*J$28+$I18*J$31+$J18*J$32 -> 0.57998558 | V18: =K$24+$C18*K$26+$D18*K$27+$E18*K$30+$F18*K$29+$G18*K$25+$H18*K$28+$I18*K$31+$J18*K$32+$M18*K$33 -> 1.4946009 | W18: =L$24+$C18*L$26+$D18*L$27+$E18*L$30+$F18*L$29+$G18*L$25+$H18*L$28+$I18*L$31+$J18*L$32+$M18*L$33 -> -0.99185153 | X18: =M$24+$C18*M$26+$D18*M$27+$E18*M$30+$F18*M$29+$G18*M$25+$H18*M$28+$I18*M$31+$J18*M$32+$M18*M$33 -> 0.81797176 | Y18: =N$24+$C18*N$26+$D18*N$27+$E18*N$30+$F18*N$29+$G18*N$25+$H18*N$28+$I18*N$31+$J18*N$32+N$33*M18 -> 1.4730656 | Z18: =O$24+$C18*O$26+$D18*O$27+$E18*O$30+$F18*O$29+$G18*O$25+$H18*O$28+$I18*O$31+$J18*O$32 -> 0.18326988 | AA18: -0.5 | AB18: 0.18295648
A19: 2024 | B19: United States | C19: 1 | D19: 5.15 | E19: -0.59 | F19: 2.8 | G19: 3.2 | H19: 20.032105 | I19: =I9/I8-1 -> 0.23560209 | J19: =(J9/J8-1)*100 -> 4.6125461 | K19: 2624 | L19: =$B$24+C19*$B$26+D19*$B$27+E19*$B$30+F19*$B$29+$B$25*G19+H19*$B$28+I19*$B$31+J19*$B$32+K19*$B$33 -> -0.98880386 | M19: =K19/K18-1 -> 0.27193408 | N19: =$D$24+C19*$D$26+D19*$D$27+E19*$D$30+F19*$D$29+G19*$D$25+H19*$D$28+I19*$D$31+J19*$D$32 -> 0.22823438 | O19: =$C$24+C19*$C$26+D19*$C$27+E19*$C$30+F19*$C$29+G19*$C$25+H19*$C$28+I19*$C$31+J19*$C$32+M19*$C$33 -> -0.013637333 | P19: =E$24+$C19*E$26+$D19*E$27+$E19*E$30+$F19*E$29+$G19*E$25+$H19*E$28+$I19*E$31+$J19*E$32 -> -5.2409242 | Q19: =F$24+$C19*F$26+$D19*F$27+$E19*F$30+$F19*F$29+$G19*F$25+$H19*F$28+$I19*F$31+$J19*F$32 -> -1.4094284 | R19: =G$24+$C19*G$26+$D19*G$27+$E19*G$30+$F19*G$29+$G19*G$25+$H19*G$28+$I19*G$31+$J19*G$32 -> 3.2898653 | S19: =H$24+$C19*H$26+$D19*H$27+$E19*H$30+$F19*H$29+$G19*H$25+$H19*H$28+$I19*H$31+$J19*H$32 -> 0.25687015 | T19: =I$24+$C19*I$26+$D19*I$27+$E19*I$30+$F19*I$29+$G19*I$25+$H19*I$28+$I19*I$31+$J19*I$32 -> -11.178591 | U19: =J$24+$C19*J$26+$D19*J$27+$E19*J$30+$F19*J$29+$G19*J$25+$H19*J$28+$I19*J$31+$J19*J$32 -> 0.59393947 | V19: =K$24+$C19*K$26+$D19*K$27+$E19*K$30+$F19*K$29+$G19*K$25+$H19*K$28+$I19*K$31+$J19*K$32+$M19*K$33 -> 1.5015905 | W19: =L$24+$C19*L$26+$D19*L$27+$E19*L$30+$F19*L$29+$G19*L$25+$H19*L$28+$I19*L$31+$J19*L$32+$M19*L$33 -> -1.4313093 | X19: =M$24+$C19*M$26+$D19*M$27+$E19*M$30+$F19*M$29+$G19*M$25+$H19*M$28+$I19*M$31+$J19*M$32+$M19*M$33 -> 0.66100065 | Y19: =N$24+$C19*N$26+$D19*N$27+$E19*N$30+$F19*N$29+$G19*N$25+$H19*N$28+$I19*N$31+$J19*N$32+N$33*M19 -> 1.1337545 | Z19: =O$24+$C19*O$26+$D19*O$27+$E19*O$30+$F19*O$29+$G19*O$25+$H19*O$28+$I19*O$31+$J19*O$32 -> 0.19197562 | AA19: -0.4 | AB19: 0.11310559
A20: 2025 | B20: United States | C20: -3 | D20: 3.7 | E20: 0.3 | F20: 1.8 | G20: 3 | H20: 18.426116 | I20: =I10/I9-1 -> 0.16760829 | J20: =(J10/J9-1)*100 -> -4.1446208 | K20: 4002 | L20: =$B$24+C20*$B$26+D20*$B$27+E20*$B$30+F20*$B$29+$B$25*G20+H20*$B$28+I20*$B$31+J20*$B$32+K20*$B$33 -> -1.8588849 | M20: =K20/K19-1 -> 0.52515244 | N20: =$D$24+C20*$D$26+D20*$D$27+E20*$D$30+F20*$D$29+G20*$D$25+H20*$D$28+I20*$D$31+J20*$D$32 -> -0.092927598 | O20: =$C$24+C20*$C$26+D20*$C$27+E20*$C$30+F20*$C$29+G20*$C$25+H20*$C$28+I20*$C$31+J20*$C$32+M20*$C$33 -> -0.57103588 | P20: =E$24+$C20*E$26+$D20*E$27+$E20*E$30+$F20*E$29+$G20*E$25+$H20*E$28+$I20*E$31+$J20*E$32 -> -4.425205 | Q20: =F$24+$C20*F$26+$D20*F$27+$E20*F$30+$F20*F$29+$G20*F$25+$H20*F$28+$I20*F$31+$J20*F$32 -> -0.86322606 | R20: =G$24+$C20*G$26+$D20*G$27+$E20*G$30+$F20*G$29+$G20*G$25+$H20*G$28+$I20*G$31+$J20*G$32 -> -0.056761438 | S20: =H$24+$C20*H$26+$D20*H$27+$E20*H$30+$F20*H$29+$G20*H$25+$H20*H$28+$I20*H$31+$J20*H$32 -> 0.67750181 | T20: =I$24+$C20*I$26+$D20*I$27+$E20*I$30+$F20*I$29+$G20*I$25+$H20*I$28+$I20*I$31+$J20*I$32 -> -6.7477302 | U20: =J$24+$C20*J$26+$D20*J$27+$E20*J$30+$F20*J$29+$G20*J$25+$H20*J$28+$I20*J$31+$J20*J$32 -> 0.59257746 | V20: =K$24+$C20*K$26+$D20*K$27+$E20*K$30+$F20*K$29+$G20*K$25+$H20*K$28+$I20*K$31+$J20*K$32+$M20*K$33 -> 1.7559206 | W20: =L$24+$C20*L$26+$D20*L$27+$E20*L$30+$F20*L$29+$G20*L$25+$H20*L$28+$I20*L$31+$J20*L$32+$M20*L$33 -> -2.5804559 | X20: =M$24+$C20*M$26+$D20*M$27+$E20*M$30+$F20*M$29+$G20*M$25+$H20*M$28+$I20*M$31+$J20*M$32+$M20*M$33 -> -0.66316184 | Y20: =N$24+$C20*N$26+$D20*N$27+$E20*N$30+$F20*N$29+$G20*N$25+$H20*N$28+$I20*N$31+$J20*N$32+N$33*M20 -> 0.027009639 | Z20: =O$24+$C20*O$26+$D20*O$27+$E20*O$30+$F20*O$29+$G20*O$25+$H20*O$28+$I20*O$31+$J20*O$32 -> -0.11618476 | AA20: -0.6 | AB20: -0.072597361
A23: {=Sheet4!A16:B26} -> 0 | B23: Coefficients | C23: W/Gold | D23: W/oGold | E23: UK30s | F23: US30s | G23: Jpy30s | H23: Fr30s | I23: UK40s | J23: 30s50s | K23: JPY | L23: SKY80s | M23: 08s | N23: GFI
A24: Intercept | B24: -0.50684193 | C24: -0.75604602 | D24: -0.79605715 | E24: 9.019127 | F24: 1.0052002 | G24: -16.598445 | H24: 1.1100424 | I24: 18.449188 | J24: -0.52522067 | K24: -1.3867738 | L24: -0.2379376 | M24: -1.2327466 | N24: -2.0468295 | O24: -0.797736
A25: CoreInflation | B25: 0.06927159 | C25: 0.078444472 | D25: 0.072165673 | E25: 0.29741496 | F25: 0.072470673 | G25: 0.062663039 | H25: 0.015434254 | I25: 0.044855215 | J25: 0.036672916 | K25: 0.23335962 | L25: 0.34981614 | M25: 0.34898491 | N25: 0.48694109 | O25: 0.071956
A26: ChangeDebt/GDP | B26: 0.012899276 | C26: 0.018437842 | D26: 0.014546767 | E26: -0.096106073 | F26: -0.047262581 | G26: -0.18053504 | H26: 0.037127583 | I26: 0.089942682 | J26: 0.011024007 | K26: -0.027677407 | L26: -0.00079746871 | M26: 0.026079131 | N26: 0.10831266 | O26: 0.014522
A27: SRi | B27: 0.014046023 | C27: 0.025806705 | D27: 0.028699794 | E27: 0.26983475 | F27: 0.1738451 | G27: 1.0997441 | H27: -0.1589894 | I27: -1.2495846 | J27: 0.12921249 | K27: 0.23023674 | L27: -0.12899302 | M27: 0.026319632 | N27: 0.011118069 | O27: 0.029848
A28: Money0/GDP | B28: -0.00020082906 | C28: 0.010017537 | D28: 0.01003807 | E28: -0.85827149 | F28: -0.16838795 | G28: 0.63822285 | H28: -0.014022138 | I28: -1.1083418 | J28: 0.0093025971 | K28: 0.021531265 | L28: -0.090272229 | M28: -0.0086057399 | N28: 0.066373606 | O28: 0.01021
A29: R.GDPg | B29: 0.1108872 | C29: 0.11754467 | D29: 0.11540019 | E29: 0.2119588 | F29: -0.010785667 | G29: 0.052579273 | H29: 0.27327383 | I29: -0.06070689 | J29: 0.080445674 | K29: 0.068622776 | L29: 0.06597228 | M29: 0.24719352 | N29: 0.45235973 | O29: 0.12093
A30: Curve | B30: 0.067144409 | C30: 0.049657046 | D30: 0.050854523 | E30: 0.017997083 | F30: 0.30045066 | G30: -1.6244738 | H30: 0.10110289 | I30: 1.1839058 | J30: 0.21049158 | K30: -0.11065041 | L30: 0.078197985 | M30: -0.0015980496 | N30: 0.65454171 | O30: 0.047288
A31: EquityG | B31: 0.37206973 | C31: 0.32033574 | D31: 0.36665575 | E31: -0.26741607 | F31: 0.6287434 | G31: 1.7345795 | H31: -1.4057824 | I31: -1.5307775 | J31: 0.57337592 | K31: -0.48502496 | L31: 1.7819422 | M31: 0.17123023 | N31: -0.28798375 | O31: 0.124157
A32: R.FXxTWI | B32: 0.009634891 | C32: 0.007633148 | D32: 0.010932311 | E32: 0.036378978 | F32: -0.013458275 | G32: -0.020517433 | H32: -0.046462811 | I32: 0.0012270718 | J32: -0.021063976 | K32: -0.023895729 | L32: 0.070982568 | M32: 0.070182709 | N32: -0.0026857732 | O32: 0.010131
A33: Gold Price | B33: -0.00045267341 | C33: -0.99706442 | K33: 1.9097302 | L33: -2.6666548 | M33: -0.99063175 | N33: -2.4748317
N38: 0.071956
N39: ChangeDebt/GDP | O39: 0.014522
N40: SRi | O40: 0.029848
N41: Money0/GDP | O41: 0.01021
N42: R.GDPg | O42: 0.12093
N43: Curve | O43: 0.047288
N44: Equityg | O44: 0.124157
N45: R.FXxTWI | O45: 0.010131

Sheet Database_filler
A1: Scenario | B1: Year | C1: Country | D1: BDG | E1: CoreInflation | F1: ChangeDebt/GDP | G1: SRi | H1: Money0/GDP | I1: R.GDPg | J1: Curve | K1: Equityg | L1: R.FXxTWI | M1: Gold Price | N1: EquityG
A2: 1 | B2: =Sheet1!B2 -> 1927 | C2: United Kingdom | D2: 0.28199117 | E2: 0.37353792 | F2: -1.3506502 | G2: 4.0868556 | H2: 11.987469 | I2: 0.23064702 | J2: -0.072862342 | K2: 85.70611 | L2: 4.1054955 | M2: 107.07419 | N2: 0.5
A3: 1 | B3: =B2+1 -> 1928 | C3: United Kingdom | D3: 0.71689755 | E3: -2.5589234 | F3: -0.39971815 | G3: 4.0350264 | H3: 12.066902 | I3: 6.4975207 | J3: -0.24342476 | K3: 94.664198 | L3: 9.422167 | M3: 107.15496 | N3: =K3/K2-1 -> 0.10452099
A4: 1 | B4: =B3+1 -> 1929 | C4: United Kingdom | D4: 0.738362 | E4: -0.45126399 | F4: -1.8073794 | G4: 5.4156717 | H4: 12.28637 | I4: 2.5388744 | J4: -0.038194575 | K4: 99.622959 | L4: 7.1643626 | M4: 105.82591 | N4: =K4/K3-1 -> 0.052382646
A5: 1 | B5: =B4+1 -> 1930 | C5: United Kingdom | D5: 0.26495661 | E5: 0.23657402 | F5: -1.2875536 | G5: 2.1033852 | H5: 11.644058 | I5: 0.75568072 | J5: -2.2639103 | K5: 85.347024 | L5: 8.8740715 | M5: 105.82591 | N5: =K5/K4-1 -> -0.14329965
A6: 1 | B6: =B5+1 -> 1931 | C6: United Kingdom | D6: -1.7358959 | E6: -3.4323984 | F6: 2.6683108 | G6: 4.5810497 | H6: 12.075461 | I6: -3.7844454 | J6: -2.1523281 | K6: 62.446277 | L6: 11.496788 | M6: 105.90179 | N6: =K6/K5-1 -> -0.26832507
A7: 1 | B7: =B6+1 -> 1932 | C7: United Kingdom | D7: -2.8903638 | E7: -1.2077726 | F7: 4.1531612 | G7: 0.56457474 | H7: 11.524908 | I7: -5.3918977 | J7: 1.1567178 | K7: 40.645234 | L7: -10.374693 | M7: 128.4883 | N7: =K7/K6-1 -> -0.34911679
A8: 1 | B8: =B7+1 -> 1933 | C8: United Kingdom | D8: -3.0129852 | E8: -3.2369513 | F8: 3.3931202 | G8: 0.091035764 | H8: 11.785805 | I8: 0.60201232 | J8: -2.5143886 | K8: 65.864333 | L8: -15.595411 | M8: 140.50849 | N8: =K8/K7-1 -> 0.62046879
A9: 1 | B9: =B8+1 -> 1934 | C9: United Kingdom | D9: -1.0919622 | E9: -0.68029179 | F9: -0.16174492 | G9: 0.85183465 | H9: 13.475126 | I9: 7.2357019 | J9: -2.3576333 | K9: 85.308871 | L9: 3.444001 | M9: 153.24094 | N9: =K9/K8-1 -> 0.29522106
A10: 1 | B10: =B9+1 -> 1935 | C10: United Kingdom | D10: -0.51255899 | E10: -0.33014715 | F10: -5.1159439 | G10: 0.208273 | H10: 12.787277 | I10: 4.8211535 | J10: -2.4581848 | K10: 86.692476 | L10: -0.075731543 | M10: 171.62001 | N10: =K10/K9-1 -> 0.016218776
A11: 1 | B11: =B10+1 -> 1936 | C11: United Kingdom | D11: -0.015177348 | E11: 0.87385235 | F11: -6.416309 | G11: 0.49323789 | H11: 12.641079 | I11: 3.8526382 | J11: -2.4396503 | K11: 95.576502 | L11: 2.2722106 | M11: 178.69849 | N11: =K11/K10-1 -> 0.10247748
A12: 2 | B12: 1926 | C12: United States | D12: {=D13:F13} -> 0.8 | E12: 2.5 | F12: 0.7 | G12: 3.4284084 | H12: 6.8628771 | I12: 6.3893175 | J12: -0.18629352 | K12: 44.346243 | L12: 8.7125749 | M12: =M13 -> 107.07419
A13: 2 | B13: =B12+1 -> 1927 | C13: United States | D13: 0.8 | E13: 2.5 | F13: 0.7 | G13: 2.7180289 | H13: 6.6657914 | I13: 1.2234462 | J13: 0.17969313 | K13: 55.17704 | L13: 2.6497006 | M13: {=M2:M11} -> 107.07419 | N13: =K13/K12-1 -> 0.24423259
A14: 2 | B14: =B13+1 -> 1928 | C14: United States | D14: 1.05 | E14: 2 | F14: 2.2 | G14: 4.528083 | H14: 6.5768026 | I14: 1.0245622 | J14: 1.0362006 | K14: 73.222453 | L14: 3.4580838 | M14: 107.15496 | N14: =K14/K13-1 -> 0.32704568
A15: 2 | B15: =B14+1 -> 1929 | C15: United States | D15: 1.3 | E15: 3.8 | F15: 2.35 | G15: 3.1678007 | H15: 6.436677 | I15: 6.4649419 | J15: 2.1251434 | K15: 108.77593 | L15: 0.76347305 | M15: 105.82591 | N15: =K15/K14-1 -> 0.48555436
A16: 2 | B16: =B15+1 -> 1930 | C16: United States | D16: 0.1 | E16: 1.27 | F16: 4.65 | G16: 1.661398 | H16: 6.4688877 | I16: -6.1532941 | J16: 0.054610628 | K16: 76.377132 | L16: 3.997006 | M16: 105.82591 | N16: =K16/K15-1 -> -0.29784898
A17: 2 | B17: =B16+1 -> 1931 | C17: United States | D17: -2.48 | E17: -6.7 | F17: 13 | G17: 1.5402544 | H17: 7.4710585 | I17: -7.0196103 | J17: -1.6258695 | K17: 49.6503 | L17: 15.04491 | M17: 105.90179 | N17: =K17/K16-1 -> -0.34993239
A18: 2 | B18: =B17+1 -> 1932 | C18: United States | D18: -3.4 | E18: -8.9 | F18: 27.8 | G18: 0.03442228 | H18: 9.1642121 | I18: -11.898055 | J18: -2.1910864 | K18: 28.072614 | L18: 23.802395 | M18: 128.4883 | N18: =K18/K17-1 -> -0.43459326
A19: 2 | B19: =B18+1 -> 1933 | C19: United States | D19: -3 | E19: -6.2 | F19: 30 | G19: 0.12196771 | H19: 9.7398188 | I19: -2.828513 | J19: -3.3231044 | K19: 38.395113 | L19: -3.4131737 | M19: 140.50849 | N19: =K19/K18-1 -> 0.36770708
A20: 2 | B20: =B19+1 -> 1934 | C20: United States | D20: -2.1 | E20: 6.2 | F20: 13.1 | G20: 0.14675429 | H20: 11.168554 | I20: 9.2035668 | J20: -3.1030372 | K20: 34.3142 | L20: -9.4760479 | M20: 153.24094 | N20: =K20/K19-1 -> -0.1062873
A21: 2 | B21: =B20+1 -> 1935 | C21: United States | D21: -1.4 | E21: 5.9 | F21: -8.2 | G21: 0.024469614 | H21: 11.74416 | I21: 9.5792665 | J21: -3.0288894 | K21: 43.618488 | L21: -2.4700599 | M21: 171.62001 | N21: =K21/K20-1 -> 0.27114978
A22: 2 | B22: =B21+1 -> 1936 | C22: United States | D22: -0.18 | E22: 5.8 | F22: -19.4 | G22: 0.13337841 | H22: 12.685003 | I22: 12.343458 | J22: -2.7934077 | K22: 53.416551 | L22: -6.6467066 | M22: 178.69849 | N22: =K22/K21-1 -> 0.22463098
A23: 3 | B23: 1925 | C23: Japan | D23: -0.6371064 | E23: -1.3471614 | F23: 4.5235066 | G23: 5.8362351 | H23: 0.19750707 | I23: 3.0641391 | J23: 1.1144459 | K23: 68.199149 | L23: 5.603979 | M23: 125.48284
A24: 3 | B24: =B23+1 -> 1926 | C24: Japan | D24: 0.27741439 | E24: -9.0513301 | F24: 3.95437 | G24: 6.5147388 | H24: 0.1954415 | I24: 2.6749427 | J24: 1.0099583 | K24: 92.733652 | L24: 11.061628 | M24: 112.48903 | N24: =K24/K23-1 -> 0.35974795
A25: 3 | B25: =B24+1 -> 1927 | C25: Japan | D25: 0.98421004 | E25: -5.5497607 | F25: 3.4443335 | G25: 5.3245992 | H25: 0.1891577 | I25: 1.5867584 | J25: 0.36906526 | K25: 95.986399 | L25: 13.297428 | M25: 102.24437 | N25: =K25/K24-1 -> 0.035076222
A26: 3 | B26: =B25+1 -> 1928 | C26: Japan | D26: 0.48955751 | E26: -4.7742598 | F26: 4.0489735 | G26: 2.2768488 | H26: 0.16951051 | I26: 5.0481463 | J26: -2.9860541 | K26: 86.592792 | L26: 8.7514274 | M26: 106.32768 | N26: =K26/K25-1 -> -0.097863937
A27: 3 | B27: =B26+1 -> 1929 | C27: Japan | D27: 0.50747039 | E27: 1.9012782 | F27: 4.463324 | G27: 2.5512843 | H27: 0.16437181 | I27: 5.3165576 | J27: -2.7331514 | K27: 82.581843 | L27: 6.914945 | M27: 105.30888 | N27: =K27/K26-1 -> -0.046319659
A28: 3 | B28: =B27+1 -> 1930 | C28: Japan | D28: -0.19105159 | E28: -2.1122794 | F28: 5.7992471 | G28: 2.8829512 | H28: 0.17380329 | I28: 0.47508807 | J28: -2.4454905 | K28: 68.202043 | L28: 10.339278 | M28: 109.39218 | N28: =K28/K27-1 -> -0.17412787
A29: 3 | B29: =B28+1 -> 1931 | C29: Japan | D29: -1.8885982 | E29: -15.966393 | F29: 10.071776 | G29: 2.0355111 | H29: 0.18496437 | I29: -3.9872505 | J29: -2.5141538 | K29: 60.593973 | L29: 3.1798222 | M29: 99.107102 | N29: =K29/K28-1 -> -0.11155193
A30: 3 | B30: =B29+1 -> 1932 | C30: Japan | D30: -1.3518544 | E30: -2.5465742 | F30: 11.003307 | G30: 6.0410274 | H30: 0.17804253 | I30: 4.2160711 | J30: 0.059760531 | K30: 50.69104 | L30: 13.903938 | M30: 143.06935 | N30: =K30/K29-1 -> -0.163431
A31: 3 | B31: =B30+1 -> 1933 | C31: Japan | D31: 1.2409345 | E31: 5.7999069 | F31: 8.55011 | G31: 3.1415273 | H31: 0.16883734 | I31: 9.2398367 | J31: -2.1166743 | K31: 44.014807 | L31: -43.374536 | M31: 237.22797 | N31: =K31/K30-1 -> -0.13170439
A32: 3 | B32: =B31+1 -> 1934 | C32: Japan | D32: 2.9095635 | E32: 2.7899178 | F32: 1.7258831 | G32: 2.3988967 | H32: 0.17189611 | I32: 5.5301683 | J32: -2.2563466 | K32: 76.248538 | L32: -25.643534 | M32: 275.69191 | N32: =K32/K31-1 -> 0.73233834
A33: 3 | B33: =B32+1 -> 1935 | C33: Japan | D33: 1.5912398 | E33: 1.5024287 | F33: -2.3801701 | G33: 2.2802965 | H33: 0.17015251 | I33: 2.437846 | J33: -2.2188163 | K33: 64.599134 | L33: -27.480016 | M33: 285.21693 | N33: =K33/K32-1 -> -0.15278199
A34: 3 | B34: =B33+1 -> 1936 | C34: Japan | D34: 0.72266593 | E34: 2.4458474 | F34: -2.5195858 | G34: 2.2685744 | H34: 0.16585529 | I34: 4.6220433 | J34: -2.1458882 | K34: 70.081632 | L34: -23.464242 | M34: 292.21919 | N34: =K34/K33-1 -> 0.084869526
A35: 4 | B35: 1926 | C35: France | D35: 1.3571352 | E35: 23.576193 | F35: -36.297961 | G35: 4.3754941 | H35: 0.16716507 | I35: 3.17246 | J35: -0.73362861 | K35: 33.10996 | L35: -34.531227 | M35: 112.2688
A36: 4 | B36: =B35+1 -> 1927 | C36: France | D36: 0.65794671 | E36: 35.24085 | F36: -29.869845 | G36: 1.9565217 | H36: 0.17797116 | I36: 1.6317947 | J36: 1.915407 | K36: 46.083724 | L36: -13.427947 | M36: 165.0811 | N36: =K36/K35-1 -> 0.39183874
A37: 4 | B37: =B36+1 -> 1928 | C37: France | D37: 0.79132227 | E37: -16.011273 | F37: -10.457392 | G37: 2.7747036 | H37: 0.18419005 | I37: 3.6556895 | J37: -1.4591971 | K37: 68.664912 | L37: -17.681652 | M37: 107.01888 | N37: =K37/K36-1 -> 0.49000353
A38: 4 | B38: =B37+1 -> 1929 | C38: France | D38: 2.0848773 | E38: 13.770645 | F38: -10.841699 | G38: 3.3794466 | H38: 0.18906485 | I38: 8.0088691 | J38: -0.91007648 | K38: 99.922407 | L38: -8.4782503 | M38: 109.45177 | N38: =K38/K37-1 -> 0.45521787
A39: 4 | B39: =B38+1 -> 1930 | C39: France | D39: 2.3456923 | E39: 2.5798115 | F39: -5.1082918 | G39: 1.8498024 | H39: 0.2187098 | I39: 5.6142089 | J39: -0.31313574 | K39: 86.359369 | L39: -8.6260024 | M39: 109.45177 | N39: =K39/K38-1 -> -0.1357357
A40: 4 | B40: =B39+1 -> 1931 | C40: France | D40: 0.49759548 | E40: 6.0499175 | F40: -0.8825522 | G40: 1.0671937 | H40: 0.26799246 | I40: -2.7716737 | J40: -1.1047563 | K40: 70.885265 | L40: 2.6925881 | M40: 106.70587 | N40: =K40/K39-1 -> -0.17918269
...

Sheet Extra
A22: M0 | B22: nGDP | C22: %
A23: 3416.9614 | B23: 17300.451 | C23: {=A23:A34/B23:B34} -> 0.19750707
A24: 3281.5405 | B24: 16790.398 | C24: 0.1954415
A25: 3078.4089 | B25: 16274.299 | C25: 0.1891577
A26: 2899.46 | B26: 17104.898 | C26: 0.16951051
A27: 2848.677 | B27: 17330.691 | C27: 0.16437181
A28: 2532.2715 | B28: 14569.756 | C28: 0.17380329
A29: 2421.1836 | B29: 13090 | C29: 0.18496437
A30: 2559.0398 | B30: 14373.194 | C30: 0.17804253
A31: 2750.4324 | B31: 16290.427 | C31: 0.16883734
A32: 2941.825 | B32: 17113.971 | C32: 0.17189611
A33: 3105.1111 | B33: 18248.988 | C33: 0.17015251
A34: 3327.2871 | B34: 20061.387 | C34: 0.16585529
A35: 8143.8267 | B35: 487.17276 | C35: {=((A35:A47)/100)/B35:B47} -> 0.16716507
A36: 8154.498 | B36: 458.19211 | C36: 0.17797116
A37: 9156.2402 | B37: 497.10831 | C37: 0.18419005
A38: 9855.3721 | B38: 521.26941 | C38: 0.18906485
A39: 10994.471 | B39: 502.69678 | C39: 0.2187098
A40: 12048.503 | B40: 449.58365 | C40: 0.26799246
A41: 12522.01 | B41: 400.58893 | C41: 0.31259002
A42: 12663.178 | B42: 374.28064 | C42: 0.33833377
A43: 12354.011 | B43: 346.06741 | C43: 0.35698279
A44: 12525.669 | B44: 307.58002 | C44: 0.40723286
A45: 12816.236 | B45: 370.63626 | C45: 0.34579013
A46: 13462.468 | B46: 521.77795 | C46: 0.25801144
A47: 15482.112 | B47: 622.87616 | C47: 0.24855843

Sheet Sheet4
A1: SUMMARY OUTPUT
A3: Regression Statistics
A4: Multiple R | B4: 0.52533343
A5: R Square | B5: 0.27597522
A6: Adjusted R Square | B6: 0.2416793
A7: Standard Error | B7: 1.0411062
A8: Observations | B8: 200
A10: ANOVA
B11: df | C11: SS | D11: MS | E11: F | F11: Significance F
A12: Regression | B12: 9 | C12: 78.498309 | D12: 8.7220343 | E12: 8.046884 | F12: 4.5065748e-10
A13: Residual | B13: 190 | C13: 205.9414 | D13: 1.0839021
A14: Total | B14: 199 | C14: 284.4397
B16: Coefficients | C16: Standard Error | D16: t Stat | E16: P-value | F16: Lower 95% | G16: Upper 95% | H16: Lower 95.0% | I16: Upper 95.0%
A17: Intercept | B17: -0.50684193 | C17: 0.26789429 | D17: -1.8919475 | E17: 0.060018966 | F17: -1.035271 | G17: 0.021587105 | H17: -1.035271 | I17: 0.021587105
A18: CoreInflation | B18: 0.06927159 | C18: 0.015098774 | D18: 4.587895 | E18: 8.1158107e-06 | F18: 0.039488833 | G18: 0.099054347 | H18: 0.039488833 | I18: 0.099054347
A19: ChangeDebt/GDP | B19: 0.012899276 | C19: 0.0080098222 | D19: 1.6104322 | E19: 0.10896361 | F19: -0.0029003245 | G19: 0.028698876 | H19: -0.0029003245 | I19: 0.028698876
A20: SRi | B20: 0.014046023 | C20: 0.022478958 | D20: 0.62485206 | E20: 0.53281783 | F20: -0.030294355 | G20: 0.058386401 | H20: -0.030294355 | I20: 0.058386401
A21: Money0/GDP | B21: -0.00020082906 | C21: 0.008299341 | D21: -0.024198194 | E21: 0.98071991 | F21: -0.016571513 | G21: 0.016169855 | H21: -0.016571513 | I21: 0.016169855
A22: R.GDPg | B22: 0.1108872 | C22: 0.023886257 | D22: 4.6423012 | E22: 6.413074e-06 | F22: 0.063770885 | G22: 0.15800352 | H22: 0.063770885 | I22: 0.15800352
A23: Curve | B23: 0.067144409 | C23: 0.036312393 | D23: 1.849077 | E23: 0.066000318 | F23: -0.0044828093 | G23: 0.13877163 | H23: -0.0044828093 | I23: 0.13877163
A24: EquityG | B24: 0.37206973 | C24: 0.33172884 | D24: 1.121608 | E24: 0.26344465 | F24: -0.28227476 | G24: 1.0264142 | H24: -0.28227476 | I24: 1.0264142
A25: R.FXxTWI | B25: 0.009634891 | C25: 0.0080775773 | D25: 1.1927946 | E25: 0.23443724 | F25: -0.0062983579 | G25: 0.02556814 | H25: -0.0062983579 | I25: 0.02556814
A26: Gold Price | B26: -0.00045267341 | C26: 0.001907953 | D26: -0.23725606 | E26: 0.81271378 | F26: -0.0042161645 | G26: 0.0033108177 | H26: -0.0042161645 | I26: 0.0033108177

Sheet Database_filler (2)
A1: Scenario | B1: Year | C1: Country | D1: BDG | E1: CoreInflation | F1: ChangeDebt/GDP | G1: SRi | H1: Money0/GDP | I1: R.GDPg | J1: Curve | K1: EquityG | L1: R.FXxTWI | M1: Gold Price
A2: 1 | B2: =Sheet1!B2 -> 1927 | C2: United Kingdom | D2: 0.28199117 | E2: 0.37353792 | F2: -1.3506502 | G2: 4.0868556 | H2: 11.987469 | I2: 0.23064702 | J2: -0.072862342 | K2: 0.07 | L2: 4.1054955 | M2: 107.07419 | N2: 0
A3: 1 | B3: =B2+1 -> 1928 | C3: United Kingdom | D3: 0.71689755 | E3: -2.5589234 | F3: -0.39971815 | G3: 4.0350264 | H3: 12.066902 | I3: 6.4975207 | J3: -0.24342476 | K3: 0.10452099 | L3: 9.422167 | M3: 107.15496 | N3: =M3/M2-1 -> 0.00075434606
A4: 1 | B4: =B3+1 -> 1929 | C4: United Kingdom | D4: 0.738362 | E4: -0.45126399 | F4: -1.8073794 | G4: 5.4156717 | H4: 12.28637 | I4: 2.5388744 | J4: -0.038194575 | K4: 0.052382646 | L4: 7.1643626 | M4: 105.82591 | N4: =M4/M3-1 -> -0.012403065
A5: 1 | B5: =B4+1 -> 1930 | C5: United Kingdom | D5: 0.26495661 | E5: 0.23657402 | F5: -1.2875536 | G5: 2.1033852 | H5: 11.644058 | I5: 0.75568072 | J5: -2.2639103 | K5: -0.14329965 | L5: 8.8740715 | M5: 105.82591 | N5: =M5/M4-1 -> 0
A6: 1 | B6: =B5+1 -> 1931 | C6: United Kingdom | D6: -1.7358959 | E6: -3.4323984 | F6: 2.6683108 | G6: 4.5810497 | H6: 12.075461 | I6: -3.7844454 | J6: -2.1523281 | K6: -0.26832507 | L6: 11.496788 | M6: 105.90179 | N6: =M6/M5-1 -> 0.00071698681
A7: 1 | B7: =B6+1 -> 1932 | C7: United Kingdom | D7: -2.8903638 | E7: -1.2077726 | F7: 4.1531612 | G7: 0.56457474 | H7: 11.524908 | I7: -5.3918977 | J7: 1.1567178 | K7: -0.34911679 | L7: -10.374693 | M7: 128.4883 | N7: =M7/M6-1 -> 0.21327786
A8: 1 | B8: =B7+1 -> 1933 | C8: United Kingdom | D8: -3.0129852 | E8: -3.2369513 | F8: 3.3931202 | G8: 0.091035764 | H8: 11.785805 | I8: 0.60201232 | J8: -2.5143886 | K8: 0.62046879 | L8: -15.595411 | M8: 140.50849 | N8: =M8/M7-1 -> 0.093550876
A9: 1 | B9: =B8+1 -> 1934 | C9: United Kingdom | D9: -1.0919622 | E9: -0.68029179 | F9: -0.16174492 | G9: 0.85183465 | H9: 13.475126 | I9: 7.2357019 | J9: -2.3576333 | K9: 0.29522106 | L9: 3.444001 | M9: 153.24094 | N9: =M9/M8-1 -> 0.090616916
A10: 1 | B10: =B9+1 -> 1935 | C10: United Kingdom | D10: -0.51255899 | E10: -0.33014715 | F10: -5.1159439 | G10: 0.208273 | H10: 12.787277 | I10: 4.8211535 | J10: -2.4581848 | K10: 0.016218776 | L10: -0.075731543 | M10: 171.62001 | N10: =M10/M9-1 -> 0.11993579
A11: 1 | B11: =B10+1 -> 1936 | C11: United Kingdom | D11: -0.015177348 | E11: 0.87385235 | F11: -6.416309 | G11: 0.49323789 | H11: 12.641079 | I11: 3.8526382 | J11: -2.4396503 | K11: 0.10247748 | L11: 2.2722106 | M11: 178.69849 | N11: =M11/M10-1 -> 0.041245053
A12: 2 | B12: 1926 | C12: United States | D12: {=D13:F13} -> 0.8 | E12: 2.5 | F12: 0.7 | G12: 3.4284084 | H12: 6.8628771 | I12: 6.3893175 | J12: -0.18629352 | K12: 0.07 | L12: 8.7125749 | M12: =M13 -> 107.07419 | N12: 0
A13: 2 | B13: =B12+1 -> 1927 | C13: United States | D13: 0.8 | E13: 2.5 | F13: 0.7 | G13: 2.7180289 | H13: 6.6657914 | I13: 1.2234462 | J13: 0.17969313 | K13: 0.24423259 | L13: 2.6497006 | M13: {=M2:M11} -> 107.07419 | N13: =M13/M12-1 -> 0
A14: 2 | B14: =B13+1 -> 1928 | C14: United States | D14: 1.05 | E14: 2 | F14: 2.2 | G14: 4.528083 | H14: 6.5768026 | I14: 1.0245622 | J14: 1.0362006 | K14: 0.32704568 | L14: 3.4580838 | M14: 107.15496 | N14: =M14/M13-1 -> 0.00075434606
A15: 2 | B15: =B14+1 -> 1929 | C15: United States | D15: 1.3 | E15: 3.8 | F15: 2.35 | G15: 3.1678007 | H15: 6.436677 | I15: 6.4649419 | J15: 2.1251434 | K15: 0.48555436 | L15: 0.76347305 | M15: 105.82591 | N15: =M15/M14-1 -> -0.012403065
A16: 2 | B16: =B15+1 -> 1930 | C16: United States | D16: 0.1 | E16: 1.27 | F16: 4.65 | G16: 1.661398 | H16: 6.4688877 | I16: -6.1532941 | J16: 0.054610628 | K16: -0.29784898 | L16: 3.997006 | M16: 105.82591 | N16: =M16/M15-1 -> 0
A17: 2 | B17: =B16+1 -> 1931 | C17: United States | D17: -2.48 | E17: -6.7 | F17: 13 | G17: 1.5402544 | H17: 7.4710585 | I17: -7.0196103 | J17: -1.6258695 | K17: -0.34993239 | L17: 15.04491 | M17: 105.90179 | N17: =M17/M16-1 -> 0.00071698681
A18: 2 | B18: =B17+1 -> 1932 | C18: United States | D18: -3.4 | E18: -8.9 | F18: 27.8 | G18: 0.03442228 | H18: 9.1642121 | I18: -11.898055 | J18: -2.1910864 | K18: -0.43459326 | L18: 23.802395 | M18: 128.4883 | N18: =M18/M17-1 -> 0.21327786
A19: 2 | B19: =B18+1 -> 1933 | C19: United States | D19: -3 | E19: -6.2 | F19: 30 | G19: 0.12196771 | H19: 9.7398188 | I19: -2.828513 | J19: -3.3231044 | K19: 0.36770708 | L19: -3.4131737 | M19: 140.50849 | N19: =M19/M18-1 -> 0.093550876
A20: 2 | B20: =B19+1 -> 1934 | C20: United States | D20: -2.1 | E20: 6.2 | F20: 13.1 | G20: 0.14675429 | H20: 11.168554 | I20: 9.2035668 | J20: -3.1030372 | K20: -0.1062873 | L20: -9.4760479 | M20: 153.24094 | N20: =M20/M19-1 -> 0.090616916
A21: 2 | B21: =B20+1 -> 1935 | C21: United States | D21: -1.4 | E21: 5.9 | F21: -8.2 | G21: 0.024469614 | H21: 11.74416 | I21: 9.5792665 | J21: -3.0288894 | K21: 0.27114978 | L21: -2.4700599 | M21: 171.62001 | N21: =M21/M20-1 -> 0.11993579
A22: 2 | B22: =B21+1 -> 1936 | C22: United States | D22: -0.18 | E22: 5.8 | F22: -19.4 | G22: 0.13337841 | H22: 12.685003 | I22: 12.343458 | J22: -2.7934077 | K22: 0.22463098 | L22: -6.6467066 | M22: 178.69849 | N22: =M22/M21-1 -> 0.041245053
A23: 3 | B23: 1925 | C23: Japan | D23: -0.6371064 | E23: -1.3471614 | F23: 4.5235066 | G23: 5.8362351 | H23: 0.19750707 | I23: 3.0641391 | J23: 1.1144459 | K23: 0.1 | L23: 5.603979 | M23: 125.48284 | N23: 0
A24: 3 | B24: =B23+1 -> 1926 | C24: Japan | D24: 0.27741439 | E24: -9.0513301 | F24: 3.95437 | G24: 6.5147388 | H24: 0.1954415 | I24: 2.6749427 | J24: 1.0099583 | K24: 0.35974795 | L24: 11.061628 | M24: 112.48903 | N24: =M24/M23-1 -> -0.10355049
A25: 3 | B25: =B24+1 -> 1927 | C25: Japan | D25: 0.98421004 | E25: -5.5497607 | F25: 3.4443335 | G25: 5.3245992 | H25: 0.1891577 | I25: 1.5867584 | J25: 0.36906526 | K25: 0.035076222 | L25: 13.297428 | M25: 102.24437 | N25: =M25/M24-1 -> -0.091072455
A26: 3 | B26: =B25+1 -> 1928 | C26: Japan | D26: 0.48955751 | E26: -4.7742598 | F26: 4.0489735 | G26: 2.2768488 | H26: 0.16951051 | I26: 5.0481463 | J26: -2.9860541 | K26: -0.097863937 | L26: 8.7514274 | M26: 106.32768 | N26: =M26/M25-1 -> 0.039936734
A27: 3 | B27: =B26+1 -> 1929 | C27: Japan | D27: 0.50747039 | E27: 1.9012782 | F27: 4.463324 | G27: 2.5512843 | H27: 0.16437181 | I27: 5.3165576 | J27: -2.7331514 | K27: -0.046319659 | L27: 6.914945 | M27: 105.30888 | N27: =M27/M26-1 -> -0.009581749
A28: 3 | B28: =B27+1 -> 1930 | C28: Japan | D28: -0.19105159 | E28: -2.1122794 | F28: 5.7992471 | G28: 2.8829512 | H28: 0.17380329 | I28: 0.47508807 | J28: -2.4454905 | K28: -0.17412787 | L28: 10.339278 | M28: 109.39218 | N28: =M28/M27-1 -> 0.03877457
A29: 3 | B29: =B28+1 -> 1931 | C29: Japan | D29: -1.8885982 | E29: -15.966393 | F29: 10.071776 | G29: 2.0355111 | H29: 0.18496437 | I29: -3.9872505 | J29: -2.5141538 | K29: -0.11155193 | L29: 3.1798222 | M29: 99.107102 | N29: =M29/M28-1 -> -0.094020253
A30: 3 | B30: =B29+1 -> 1932 | C30: Japan | D30: -1.3518544 | E30: -2.5465742 | F30: 11.003307 | G30: 6.0410274 | H30: 0.17804253 | I30: 4.2160711 | J30: 0.059760531 | K30: -0.163431 | L30: 13.903938 | M30: 143.06935 | N30: =M30/M29-1 -> 0.44358326
A31: 3 | B31: =B30+1 -> 1933 | C31: Japan | D31: 1.2409345 | E31: 5.7999069 | F31: 8.55011 | G31: 3.1415273 | H31: 0.16883734 | I31: 9.2398367 | J31: -2.1166743 | K31: -0.13170439 | L31: -43.374536 | M31: 237.22797 | N31: =M31/M30-1 -> 0.6581327
A32: 3 | B32: =B31+1 -> 1934 | C32: Japan | D32: 2.9095635 | E32: 2.7899178 | F32: 1.7258831 | G32: 2.3988967 | H32: 0.17189611 | I32: 5.5301683 | J32: -2.2563466 | K32: 0.73233834 | L32: -25.643534 | M32: 275.69191 | N32: =M32/M31-1 -> 0.16213913
A33: 3 | B33: =B32+1 -> 1935 | C33: Japan | D33: 1.5912398 | E33: 1.5024287 | F33: -2.3801701 | G33: 2.2802965 | H33: 0.17015251 | I33: 2.437846 | J33: -2.2188163 | K33: -0.15278199 | L33: -27.480016 | M33: 285.21693 | N33: =M33/M32-1 -> 0.034549507
A34: 3 | B34: =B33+1 -> 1936 | C34: Japan | D34: 0.72266593 | E34: 2.4458474 | F34: -2.5195858 | G34: 2.2685744 | H34: 0.16585529 | I34: 4.6220433 | J34: -2.1458882 | K34: 0.084869526 | L34: -23.464242 | M34: 292.21919 | N34: =M34/M33-1 -> 0.024550661
A35: 4 | B35: 1926 | C35: France | D35: 1.3571352 | E35: 23.576193 | F35: -36.297961 | G35: 4.3754941 | H35: 0.16716507 | I35: 3.17246 | J35: -0.73362861 | K35: 0.2 | L35: -34.531227 | M35: 112.2688 | N35: 0
A36: 4 | B36: =B35+1 -> 1927 | C36: France | D36: 0.65794671 | E36: 35.24085 | F36: -29.869845 | G36: 1.9565217 | H36: 0.17797116 | I36: 1.6317947 | J36: 1.915407 | K36: 0.39183874 | L36: -13.427947 | M36: 165.0811 | N36: =M36/M35-1 -> 0.47040933
A37: 4 | B37: =B36+1 -> 1928 | C37: France | D37: 0.79132227 | E37: -16.011273 | F37: -10.457392 | G37: 2.7747036 | H37: 0.18419005 | I37: 3.6556895 | J37: -1.4591971 | K37: 0.49000353 | L37: -17.681652 | M37: 107.01888 | N37: =M37/M36-1 -> -0.35171938
A38: 4 | B38: =B37+1 -> 1929 | C38: France | D38: 2.0848773 | E38: 13.770645 | F38: -10.841699 | G38: 3.3794466 | H38: 0.18906485 | I38: 8.0088691 | J38: -0.91007648 | K38: 0.45521787 | L38: -8.4782503 | M38: 109.45177 | N38: =M38/M37-1 -> 0.022733316
A39: 4 | B39: =B38+1 -> 1930 | C39: France | D39: 2.3456923 | E39: 2.5798115 | F39: -5.1082918 | G39: 1.8498024 | H39: 0.2187098 | I39: 5.6142089 | J39: -0.31313574 | K39: -0.1357357 | L39: -8.6260024 | M39: 109.45177 | N39: =M39/M38-1 -> 0
A40: 4 | B40: =B39+1 -> 1931 | C40: France | D40: 0.49759548 | E40: 6.0499175 | F40: -0.8825522 | G40: 1.0671937 | H40: 0.26799246 | I40: -2.7716737 | J40: -1.1047563 | K40: -0.17918269 | L40: 2.6925881 | M40: 106.70587 | N40: =M40/M39-1 -> -0.025087742
...

Sheet Sheet20
A1: SUMMARY OUTPUT
A3: Regression Statistics
A4: Multiple R | B4: 0.63361807
A5: R Square | B5: 0.40147185
A6: Adjusted R Square | B6: 0.3203155
A7: Standard Error | B7: 1.0625027
A8: Observations | B8: 68
A10: ANOVA
B11: df | C11: SS | D11: MS | E11: F | F11: Significance F
A12: Regression | B12: 8 | C12: 44.676862 | D12: 5.5846077 | E12: 4.9468934 | F12: 0.00010379911
A13: Residual | B13: 59 | C13: 66.605813 | D13: 1.1289121
A14: Total | B14: 67 | C14: 111.28267
B16: Coefficients | C16: Standard Error | D16: t Stat | E16: P-value | F16: Lower 95% | G16: Upper 95% | H16: Lower 95.0% | I16: Upper 95.0%
A17: Intercept | B17: -0.52522067 | C17: 0.43586387 | D17: -1.2050108 | E17: 0.23301031 | F17: -1.3973823 | G17: 0.34694092 | H17: -1.3973823 | I17: 0.34694092
A18: CoreInflation | B18: 0.036672916 | C18: 0.019093682 | D18: 1.9206833 | E18: 0.059608443 | F18: -0.0015334536 | G18: 0.074879286 | H18: -0.0015334536 | I18: 0.074879286
A19: ChangeDebt/GDP | B19: 0.011024007 | C19: 0.0128746 | D19: 0.85626016 | E19: 0.39531824 | F19: -0.014738008 | G19: 0.036786022 | H19: -0.014738008 | I19: 0.036786022
A20: SRi | B20: 0.12921249 | C20: 0.10704833 | D20: 1.2070482 | E20: 0.23223069 | F20: -0.084990717 | G20: 0.34341571 | H20: -0.084990717 | I20: 0.34341571
A21: Money0/GDP | B21: 0.0093025971 | C21: 0.021145832 | D21: 0.43992579 | E21: 0.66159823 | F21: -0.033010116 | G21: 0.05161531 | H21: -0.033010116 | I21: 0.05161531
A22: R.GDPg | B22: 0.080445674 | C22: 0.035140311 | D22: 2.2892704 | E22: 0.025658895 | F22: 0.010130075 | G22: 0.15076127 | H22: 0.010130075 | I22: 0.15076127
A23: Curve | B23: 0.21049158 | C23: 0.14778993 | D23: 1.424262 | E23: 0.15963848 | F23: -0.085235389 | G23: 0.50621855 | H23: -0.085235389 | I23: 0.50621855
A24: EquityG | B24: 0.57337592 | C24: 0.59179069 | D24: 0.96888298 | E24: 0.33655874 | F24: -0.61079451 | G24: 1.7575464 | H24: -0.61079451 | I24: 1.7575464
A25: R.FXxTWI | B25: -0.021063976 | C25: 0.010247222 | D25: -2.0555791 | E25: 0.044257262 | F25: -0.041568619 | G25: -0.00055933202 | H25: -0.041568619 | I25: -0.00055933202

Sheet Sheet21
A1: SUMMARY OUTPUT
A3: Regression Statistics
A4: Multiple R | B4: 0.92040358
A5: R Square | B5: 0.84714274
A6: Adjusted R Square | B6: 0.76621831
A7: Standard Error | B7: 0.38346901
A8: Observations | B8: 27
A10: ANOVA
B11: df | C11: SS | D11: MS | E11: F | F11: Significance F
A12: Regression | B12: 9 | C12: 13.854154 | D12: 1.5393504 | E12: 10.468319 | F12: 2.407132e-05
A13: Residual | B13: 17 | C13: 2.4998242 | D13: 0.14704848
A14: Total | B14: 26 | C14: 16.353978
B16: Coefficients | C16: Standard Error | D16: t Stat | E16: P-value | F16: Lower 95% | G16: Upper 95% | H16: Lower 95.0% | I16: Upper 95.0%
A17: Intercept | B17: -1.3867738 | C17: 0.37942298 | D17: -3.6549548 | E17: 0.0019605022 | F17: -2.1872864 | G17: -0.58626133 | H17: -2.1872864 | I17: -0.58626133
A18: X Variable 1 | B18: 0.23335962 | C18: 0.15497288 | D18: 1.5058094 | E18: 0.15047084 | F18: -0.093604585 | G18: 0.56032382 | H18: -0.093604585 | I18: 0.56032382
A19: X Variable 2 | B19: -0.027677407 | C19: 0.025051773 | D19: -1.1048083 | E19: 0.28463469 | F19: -0.080532028 | G19: 0.025177214 | H19: -0.080532028 | I19: 0.025177214
A20: X Variable 3 | B20: 0.23023674 | C20: 0.1016815 | D20: 2.2642932 | E20: 0.036920986 | F20: 0.015707515 | G20: 0.44476596 | H20: 0.015707515 | I20: 0.44476596
A21: X Variable 4 | B21: 0.021531265 | C21: 0.0065072763 | D21: 3.3087983 | E21: 0.0041505003 | F21: 0.007802112 | G21: 0.035260418 | H21: 0.007802112 | I21: 0.035260418
A22: X Variable 5 | B22: 0.068622776 | C22: 0.038721739 | D22: 1.7722029 | E22: 0.094281229 | F22: -0.013072951 | G22: 0.1503185 | H22: -0.013072951 | I22: 0.1503185
A23: X Variable 6 | B23: -0.11065041 | C23: 0.18937616 | D23: -0.58428903 | E23: 0.56669952 | F23: -0.5101992 | G23: 0.28889837 | H23: -0.5101992 | I23: 0.28889837
A24: X Variable 7 | B24: -0.48502496 | C24: 0.52539017 | D24: -0.92317098 | E24: 0.36883616 | F24: -1.5935013 | G24: 0.62345141 | H24: -1.5935013 | I24: 0.62345141
A25: X Variable 8 | B25: -0.023895729 | C25: 0.010135148 | D25: -2.3577089 | E25: 0.030631394 | F25: -0.045279023 | G25: -0.0025124353 | H25: -0.045279023 | I25: -0.0025124353
A26: X Variable 9 | B26: 1.9097302 | C26: 0.73305878 | D26: 2.6051529 | E26: 0.018481984 | F26: 0.36311138 | G26: 3.456349 | H26: 0.36311138 | I26: 3.456349

Sheet Sheet22
A1: SUMMARY OUTPUT
A3: Regression Statistics
A4: Multiple R | B4: 0.80430265
A5: R Square | B5: 0.64690275
